<?xml version="1.0"?>
<robot name="/home/jagadeesh97/Documents/Robot.urdf" xmlns:xacro="http://ros.org/wiki/xacro">
  <link name="base_link">
    <visual>
      <origin xyz="0 0 0.0415" rpy="0 0 0"/>
      <geometry>
        <cylinder radius="0.045" length="0.08"/>
      </geometry>
    </visual>
    <collision>
      <origin xyz="0 0 0.0415" rpy="0 0 0"/>
      <geometry>
        <cylinder radius="0.045" length="0.08"/>
      </geometry>
    </collision>
  </link>
  <link name="solid(3)">
  </link>
  <joint name="base_link_solid(3)_joint" type="fixed">
    <parent link="base_link"/>
    <child link="solid(3)"/>
    <origin xyz="0.015 -0.045 0.07" rpy="0 0 0"/>
  </joint>
  <link name="solid(2)">
  </link>
  <joint name="base_link_solid(2)_joint" type="fixed">
    <parent link="base_link"/>
    <child link="solid(2)"/>
    <origin xyz="-0.015 -0.045 0.07" rpy="0 0 0"/>
  </joint>
  <joint name="motor_2" type="continuous">
    <parent link="base_link"/>
    <child link="solid(1)"/>
    <axis xyz="0.000796 0 1"/>
    <limit effort="10" velocity="10"/>
    <origin xyz="-0.045 0 0.025" rpy="0 1.57 0"/>
  </joint>
  <link name="solid(1)">
    <visual>
      <geometry>
        <cylinder radius="0.025" length="0.01"/>
      </geometry>
    </visual>
    <collision>
      <geometry>
        <cylinder radius="0.025" length="0.01"/>
      </geometry>
    </collision>
  </link>
  <joint name="motor_1" type="continuous">
    <parent link="base_link"/>
    <child link="solid"/>
    <axis xyz="0.000796 0 1"/>
    <limit effort="10" velocity="10"/>
    <origin xyz="0.045 0 0.025" rpy="0.000006 1.57 0.000006"/>
  </joint>
  <link name="solid">
    <visual>
      <geometry>
        <cylinder radius="0.025" length="0.01"/>
      </geometry>
    </visual>
    <collision>
      <geometry>
        <cylinder radius="0.025" length="0.01"/>
      </geometry>
    </collision>
  </link>
</robot>
